Workbook

Sheet Report Tracker
A1: INTELLEGO INVESTMENT CONSULTANTS · Q1 2026 REPORT TRACKER
A3: Client Name | B3: CRM | C3: Operations | D3: Submitted | E3: Reviewed | F3: Sent to Client | G3: Due Date | H3: Status | M3: KEY | N3: ✓
C4: =COUNTA(A5:A78) -> 74 | D4: =COUNTIF(D5:D500,"✓") -> 67 | E4: =COUNTIF(E5:E500,"✓") -> 45 | F4: =COUNTIF(F5:F500,"✓") -> 42
A5: MCAZ | B5: Tapiwa | C5: Anotida | D5: ✓ | E5: ✓ | F5: ✓ | G5: 20/04/26 | H5: =IF(AND(D5="✓",E5="✓",F5="✓"),"Complete",IF(E5="✓","Reviewed",IF(D5="✓","Submitted","Pending"))) -> Complete
A6: St Johns | B6: Tari | C6: Anotida | D6: ✓ | E6: ✓ | F6: ✓ | G6: 23/04/26 | H6: =IF(AND(D6="✓",E6="✓",F6="✓"),"Complete",IF(E6="✓","Reviewed",IF(D6="✓","Submitted","Pending"))) -> Complete
A7: Mashonaland Tobacco Company | B7: Tari | C7: Anotida | D7: ✓ | E7: ✓ | G7: 21/04/26 | H7: =IF(AND(D7="✓",E7="✓",F7="✓"),"Complete",IF(E7="✓","Reviewed",IF(D7="✓","Submitted","Pending"))) -> Reviewed
A8: The Joseph Pension Fund | B8: Tari | C8: Anotida | D8: ✓ | E8: ✓ | F8: ✓ | G8: 46117 | H8: =IF(AND(D8="✓",E8="✓",F8="✓"),"Complete",IF(E8="✓","Reviewed",IF(D8="✓","Submitted","Pending"))) -> Complete
A9: AGS | B9: Tari | C9: Anotida | D9: ✓ | E9: ✓ | F9: ✓ | G9: 30/04/26 | H9: =IF(AND(D9="✓",E9="✓",F9="✓"),"Complete",IF(E9="✓","Reviewed",IF(D9="✓","Submitted","Pending"))) -> Complete
A10: Triangle Senior Staff | B10: Tari | C10: Anotida | D10: ✓ | E10: ✓ | F10: ✓ | G10: 22/04/26 | H10: =IF(AND(D10="✓",E10="✓",F10="✓"),"Complete",IF(E10="✓","Reviewed",IF(D10="✓","Submitted","Pending"))) -> Complete
A11: Sandvik Pension Fund | B11: Tari | C11: Anotida | D11: ✓ | G11: 26/04/26 | H11: =IF(AND(D11="✓",E11="✓",F11="✓"),"Complete",IF(E11="✓","Reviewed",IF(D11="✓","Submitted","Pending"))) -> Submitted
A12: United Refineries | B12: Tatenda | C12: Anotida | D12: ✓ | G12: 27/04/26 | H12: =IF(AND(D12="✓",E12="✓",F12="✓"),"Complete",IF(E12="✓","Reviewed",IF(D12="✓","Submitted","Pending"))) -> Submitted
A13: Larfarge PF (Actives) | B13: Tatenda | C13: Anotida | D13: ✓ | G13: 20/04/26 | H13: =IF(AND(D13="✓",E13="✓",F13="✓"),"Complete",IF(E13="✓","Reviewed",IF(D13="✓","Submitted","Pending"))) -> Submitted
A14: Larfarge PF (Pensioners) | B14: Tatenda | C14: Anotida | D14: ✓ | G14: 21/04/26 | H14: =IF(AND(D14="✓",E14="✓",F14="✓"),"Complete",IF(E14="✓","Reviewed",IF(D14="✓","Submitted","Pending"))) -> Submitted
A15: Mimosa Corporate Funds | B15: Tino | C15: Anotida | D15: ✓ | E15: ✓ | F15: ✓ | G15: 26/04/26 | H15: =IF(AND(D15="✓",E15="✓",F15="✓"),"Complete",IF(E15="✓","Reviewed",IF(D15="✓","Submitted","Pending"))) -> Complete
A16: Zimnat Funds | B16: Tino | C16: Anotida | D16: ✓ | E16: ✓ | F16: ✓ | G16: 30/04/26 | H16: =IF(AND(D16="✓",E16="✓",F16="✓"),"Complete",IF(E16="✓","Reviewed",IF(D16="✓","Submitted","Pending"))) -> Complete
A17: Whitestone School Trust PF | B17: Tino | C17: Anotida | D17: ✓ | E17: ✓ | F17: ✓ | G17: 22/04/26 | H17: =IF(AND(D17="✓",E17="✓",F17="✓"),"Complete",IF(E17="✓","Reviewed",IF(D17="✓","Submitted","Pending"))) -> Complete
A18: Marsh Employees PF | B18: Tapiwa | C18: Arnold | D18: ✓ | G18: 27/04/26 | H18: =IF(AND(D18="✓",E18="✓",F18="✓"),"Complete",IF(E18="✓","Reviewed",IF(D18="✓","Submitted","Pending"))) -> Submitted
A19: Zimnat Group Staff PF | B19: Tatenda | C19: Arnold | H19: =IF(AND(D19="✓",E19="✓",F19="✓"),"Complete",IF(E19="✓","Reviewed",IF(D19="✓","Submitted","Pending"))) -> Pending | I19: IPS Training Workshop Needed
A20: Falcon College PF | B20: Tino | C20: Arnold | D20: ✓ | E20: ✓ | F20: ✓ | G20: 27/04/26 | H20: =IF(AND(D20="✓",E20="✓",F20="✓"),"Complete",IF(E20="✓","Reviewed",IF(D20="✓","Submitted","Pending"))) -> Complete
A21: Girls College | B21: Tino | C21: Arnold | D21: ✓ | E21: ✓ | F21: ✓ | G21: 28/04/26 | H21: =IF(AND(D21="✓",E21="✓",F21="✓"),"Complete",IF(E21="✓","Reviewed",IF(D21="✓","Submitted","Pending"))) -> Complete
A22: Masiyephambili Schools Trust PF | B22: Tino | C22: Arnold | D22: ✓ | E22: ✓ | F22: ✓ | G22: 29/04/26 | H22: =IF(AND(D22="✓",E22="✓",F22="✓"),"Complete",IF(E22="✓","Reviewed",IF(D22="✓","Submitted","Pending"))) -> Complete
A23: Minerva Provident | B23: Tino | C23: Arnold | D23: ✓ | E23: ✓ | F23: ✓ | G23: 20/04/26 | H23: =IF(AND(D23="✓",E23="✓",F23="✓"),"Complete",IF(E23="✓","Reviewed",IF(D23="✓","Submitted","Pending"))) -> Complete
A24: Minerva Risk Advisors | B24: Tino | C24: Arnold | D24: ✓ | E24: ✓ | F24: ✓ | G24: 20/04/26 | H24: =IF(AND(D24="✓",E24="✓",F24="✓"),"Complete",IF(E24="✓","Reviewed",IF(D24="✓","Submitted","Pending"))) -> Complete
A25: Minerva Umbrella Fund | B25: Tino | C25: Arnold | D25: ✓ | E25: ✓ | F25: ✓ | G25: 21/04/26 | H25: =IF(AND(D25="✓",E25="✓",F25="✓"),"Complete",IF(E25="✓","Reviewed",IF(D25="✓","Submitted","Pending"))) -> Complete
A26: TIMB Pension Fund | B26: Tapiwa | C26: Arnold | D26: ✓ | E26: ✓ | F26: ✓ | G26: 17/04/26 | H26: =IF(AND(D26="✓",E26="✓",F26="✓"),"Complete",IF(E26="✓","Reviewed",IF(D26="✓","Submitted","Pending"))) -> Complete
A27: Petrotrade Pension Fund | B27: Tari | C27: Arnold | D27: ✓ | E27: ✓ | F27: ✓ | G27: 21/04/26 | H27: =IF(AND(D27="✓",E27="✓",F27="✓"),"Complete",IF(E27="✓","Reviewed",IF(D27="✓","Submitted","Pending"))) -> Complete
A28: Edgars Actives PF | B28: Tino | C28: Arnold | D28: ✓ | E28: ✓ | F28: ✓ | G28: 23/04/26 | H28: =IF(AND(D28="✓",E28="✓",F28="✓"),"Complete",IF(E28="✓","Reviewed",IF(D28="✓","Submitted","Pending"))) -> Complete
A29: Edgars Pensioners PF | B29: Tino | C29: Arnold | D29: ✓ | E29: ✓ | F29: ✓ | G29: 24/04/26 | H29: =IF(AND(D29="✓",E29="✓",F29="✓"),"Complete",IF(E29="✓","Reviewed",IF(D29="✓","Submitted","Pending"))) -> Complete
A30: EY Pension Fund | B30: Tapiwa | C30: Elizabeth | D30: ✓ | E30: ✓ | F30: ✓ | G30: 17/04/25 | H30: =IF(AND(D30="✓",E30="✓",F30="✓"),"Complete",IF(E30="✓","Reviewed",IF(D30="✓","Submitted","Pending"))) -> Complete
A31: Zimsec Pension Fund | B31: Tapiwa | C31: Elizabeth | D31: ✓ | G31: 21/04/26 | H31: =IF(AND(D31="✓",E31="✓",F31="✓"),"Complete",IF(E31="✓","Reviewed",IF(D31="✓","Submitted","Pending"))) -> Submitted
A32: Zambezi River Authority | B32: Tapiwa | C32: Elizabeth | D32: ✓ | G32: 23/04/26 | H32: =IF(AND(D32="✓",E32="✓",F32="✓"),"Complete",IF(E32="✓","Reviewed",IF(D32="✓","Submitted","Pending"))) -> Submitted
A33: NBS | B33: Tapiwa | C33: Elizabeth | D33: ✓ | G33: 22/04/26 | H33: =IF(AND(D33="✓",E33="✓",F33="✓"),"Complete",IF(E33="✓","Reviewed",IF(D33="✓","Submitted","Pending"))) -> Submitted
A34: Goldridge | B34: Tapiwa | C34: Elizabeth | D34: ✓ | E34: ✓ | F34: ✓ | G34: 30/4/2026 | H34: =IF(AND(D34="✓",E34="✓",F34="✓"),"Complete",IF(E34="✓","Reviewed",IF(D34="✓","Submitted","Pending"))) -> Complete
A35: Unilever Zimbabwe PF | B35: Tapiwa | C35: Elizabeth | D35: ✓ | E35: ✓ | F35: ✓ | G35: 20/04/26 | H35: =IF(AND(D35="✓",E35="✓",F35="✓"),"Complete",IF(E35="✓","Reviewed",IF(D35="✓","Submitted","Pending"))) -> Complete
A36: ABC | B36: Tapiwa | C36: Elizabeth | D36: ✓ | E36: ✓ | F36: ✓ | G36: 24/04/26 | H36: =IF(AND(D36="✓",E36="✓",F36="✓"),"Complete",IF(E36="✓","Reviewed",IF(D36="✓","Submitted","Pending"))) -> Complete
A37: Zimplow | B37: Tatenda | C37: Elizabeth | D37: ✓ | G37: 30/04/26 | H37: =IF(AND(D37="✓",E37="✓",F37="✓"),"Complete",IF(E37="✓","Reviewed",IF(D37="✓","Submitted","Pending"))) -> Submitted
A38: BPB Gypsum / Saint Gobain | B38: Tapiwa | C38: Elizabeth | D38: ✓ | G38: 29/04/26 | H38: =IF(AND(D38="✓",E38="✓",F38="✓"),"Complete",IF(E38="✓","Reviewed",IF(D38="✓","Submitted","Pending"))) -> Submitted
A39: Econet | B39: Tari | C39: Elizabeth | G39: 30/04/26 | H39: =IF(AND(D39="✓",E39="✓",F39="✓"),"Complete",IF(E39="✓","Reviewed",IF(D39="✓","Submitted","Pending"))) -> Pending
A40: Seedco | B40: Tatenda | C40: Elizabeth | D40: ✓ | G40: 24/04/26 | H40: =IF(AND(D40="✓",E40="✓",F40="✓"),"Complete",IF(E40="✓","Reviewed",IF(D40="✓","Submitted","Pending"))) -> Submitted
A41: Zimasco Pension Fund | B41: Tapiwa | C41: Elizabeth | D41: ✓ | G41: 24/04/26 | H41: =IF(AND(D41="✓",E41="✓",F41="✓"),"Complete",IF(E41="✓","Reviewed",IF(D41="✓","Submitted","Pending"))) -> Submitted
...

Sheet Dashboard
A2: INTELLEGO INVESTMENT CONSULTANTS · Q1 2026 DASHBOARD
B4: Q4 2025 INVESTMENT REPORT PROGRESS · Last Updated: 15 May 2026
B5: Total Clients | C5: Submitted | D5: Reviewed | E5: Sent to Client | F5: Completion Rate | G5: Outstanding
B6: ='Report Tracker'!C4 -> 74 | C6: ='Report Tracker'!D4 -> 67 | D6: ='Report Tracker'!E4 -> 45 | E6: ='Report Tracker'!F4 -> 42 | F6: =IF('Report Tracker'!C4>0,'Report Tracker'!F4/'Report Tracker'!C4,0) -> 0.56756757 | G6: ='Report Tracker'!C4-'Report Tracker'!F4 -> 32
B8: PROGRESS BY CRM CONSULTANT
B9: CRM | C9: Clients | D9: Submitted | E9: Reviewed | F9: Sent | G9: % Done
B10: Tapiwa | C10: =COUNTIF('Report Tracker'!B:B,"Tapiwa") -> 18 | D10: =COUNTIFS('Report Tracker'!B:B,"Tapiwa",'Report Tracker'!D:D,"✓") -> 15 | E10: =COUNTIFS('Report Tracker'!B:B,"Tapiwa",'Report Tracker'!E:E,"✓") -> 7 | F10: =COUNTIFS('Report Tracker'!B:B,"Tapiwa",'Report Tracker'!F:F,"✓") -> 7 | G10: =IF(C10>0,F10/C10,0) -> 0.38888889
B11: Tari | C11: =COUNTIF('Report Tracker'!B:B,"Tari") -> 22 | D11: =COUNTIFS('Report Tracker'!B:B,"Tari",'Report Tracker'!D:D,"✓") -> 20 | E11: =COUNTIFS('Report Tracker'!B:B,"Tari",'Report Tracker'!E:E,"✓") -> 16 | F11: =COUNTIFS('Report Tracker'!B:B,"Tari",'Report Tracker'!F:F,"✓") -> 15 | G11: =IF(C11>0,F11/C11,0) -> 0.68181818
B12: Tatenda | C12: =COUNTIF('Report Tracker'!B:B,"Tatenda") -> 18 | D12: =COUNTIFS('Report Tracker'!B:B,"Tatenda",'Report Tracker'!D:D,"✓") -> 16 | E12: =COUNTIFS('Report Tracker'!B:B,"Tatenda",'Report Tracker'!E:E,"✓") -> 6 | F12: =COUNTIFS('Report Tracker'!B:B,"Tatenda",'Report Tracker'!F:F,"✓") -> 6 | G12: =IF(C12>0,F12/C12,0) -> 0.33333333
B13: Tino/Edwin | C13: =COUNTIF('Report Tracker'!B:B,"Tino") -> 16 | D13: =COUNTIFS('Report Tracker'!B:B,"Tino",'Report Tracker'!D:D,"✓") -> 16 | E13: =COUNTIFS('Report Tracker'!B:B,"Tino",'Report Tracker'!E:E,"✓") -> 16 | F13: =COUNTIFS('Report Tracker'!B:B,"Tino",'Report Tracker'!F:F,"✓") -> 14 | G13: =IF(C13>0,F13/C13,0) -> 0.875
B14: TOTAL | C14: =SUM(C10:C13) -> 74 | D14: =SUM(D10:D13) -> 67 | E14: =SUM(E10:E13) -> 45 | F14: =SUM(F10:F13) -> 42 | G14: =IF(C14>0,F14/C14,0) -> 0.56756757
B16: PROGRESS BY OPERATIONS STAFF
B17: Operations | C17: Clients | D17: Submitted | E17: Reviewed | F17: Sent | G17: % Done
B18: Anotida | C18: =COUNTIF('Report Tracker'!C:C,"Anotida") -> 13 | D18: =COUNTIFS('Report Tracker'!C:C,"Anotida",'Report Tracker'!D:D,"✓") -> 13 | E18: =COUNTIFS('Report Tracker'!C:C,"Anotida",'Report Tracker'!E:E,"✓") -> 9 | F18: =COUNTIFS('Report Tracker'!C:C,"Anotida",'Report Tracker'!F:F,"✓") -> 8 | G18: =IF(C18>0,D18/C18,0) -> 1
B19: Arnold | C19: =COUNTIF('Report Tracker'!C:C,"Arnold") -> 12 | D19: =COUNTIFS('Report Tracker'!C:C,"Arnold",'Report Tracker'!D:D,"✓") -> 11 | E19: =COUNTIFS('Report Tracker'!C:C,"Arnold",'Report Tracker'!E:E,"✓") -> 10 | F19: =COUNTIFS('Report Tracker'!C:C,"Arnold",'Report Tracker'!F:F,"✓") -> 10 | G19: =IF(C19>0,D19/C19,0) -> 0.91666667
B20: William | C20: =COUNTIF('Report Tracker'!C:C,"William") -> 13 | D20: =COUNTIFS('Report Tracker'!C:C,"William",'Report Tracker'!D:D,"✓") -> 11 | E20: =COUNTIFS('Report Tracker'!C:C,"William",'Report Tracker'!E:E,"✓") -> 10 | F20: =COUNTIFS('Report Tracker'!C:C,"William",'Report Tracker'!F:F,"✓") -> 10 | G20: =IF(C20>0,D20/C20,0) -> 0.84615385
B21: Elizabeth | C21: =COUNTIF('Report Tracker'!C:C,"Elizabeth") -> 12 | D21: =COUNTIFS('Report Tracker'!C:C,"Elizabeth",'Report Tracker'!D:D,"✓") -> 11 | E21: =COUNTIFS('Report Tracker'!C:C,"Elizabeth",'Report Tracker'!E:E,"✓") -> 4 | F21: =COUNTIFS('Report Tracker'!C:C,"Elizabeth",'Report Tracker'!F:F,"✓") -> 4 | G21: =IF(C21>0,D21/C21,0) -> 0.91666667 | M21: =11/74 -> 0.14864865
B22: Elvis | C22: =COUNTIF('Report Tracker'!C:C,"Elvis") -> 11 | D22: =COUNTIFS('Report Tracker'!C:C,"Elvis",'Report Tracker'!D:D,"✓") -> 10 | E22: =COUNTIFS('Report Tracker'!C:C,"Elvis",'Report Tracker'!E:E,"✓") -> 4 | F22: =COUNTIFS('Report Tracker'!C:C,"Elvis",'Report Tracker'!F:F,"✓") -> 4 | G22: =IF(C22>0,D22/C22,0) -> 0.90909091
B23: Godfrey | C23: =COUNTIF('Report Tracker'!C:C,"Godfrey") -> 13 | D23: =COUNTIFS('Report Tracker'!C:C,"Godfrey",'Report Tracker'!D:D,"✓") -> 11 | E23: =COUNTIFS('Report Tracker'!C:C,"Godfrey",'Report Tracker'!E:E,"✓") -> 8 | F23: =COUNTIFS('Report Tracker'!C:C,"Godfrey",'Report Tracker'!F:F,"✓") -> 6 | G23: =IF(C23>0,D23/C23,0) -> 0.84615385
B24: TOTAL | C24: =SUM(C18:C23) -> 74 | D24: =SUM(D18:D23) -> 67 | E24: =SUM(E18:E23) -> 45 | F24: =SUM(F18:F23) -> 42 | G24: =IF(C24>0,D24/C24,0) -> 0.90540541

Sheet By Operations
A2: INTELLEGO · Q1 2026 REPORTS — VIEW BY OPERATIONS STAFF
B4: ANOTIDA — 13 clients
A5: # | B5: Client | C5: CRM | D5: Submitted | E5: Reviewed | F5: Sent | G5: Due | H5: Status
A6: 1 | B6: MCAZ | C6: Tapiwa | G6: 20/04/26 | H6: ='Report Tracker'!H5 -> Complete
A7: 2 | B7: St Johns | C7: Tari | G7: 23/04/26 | H7: ='Report Tracker'!H6 -> Complete
A8: 3 | B8: Mashonaland Tobacco Company | C8: Tari | G8: 21/04/26 | H8: ='Report Tracker'!H7 -> Reviewed
A9: 4 | B9: The Joseph Pension Fund | C9: Tari | G9: 30/04/26 | H9: ='Report Tracker'!H8 -> Complete
A10: 5 | B10: AGS | C10: Tari | G10: 30/04/26 | H10: ='Report Tracker'!H9 -> Complete
A11: 6 | B11: Triangle Senior Staff | C11: Tari | G11: 22/04/26 | H11: ='Report Tracker'!H10 -> Complete
A12: 7 | B12: Sandvik Pension Fund | C12: Tari | G12: 26/04/26 | H12: ='Report Tracker'!H11 -> Submitted
A13: 8 | B13: United Refineries | C13: Tatenda | G13: 27/04/26 | H13: ='Report Tracker'!H12 -> Submitted
A14: 9 | B14: Larfarge PF (Actives) | C14: Tatenda | G14: 20/04/26 | H14: ='Report Tracker'!H13 -> Submitted
A15: 10 | B15: Larfarge PF (Pensioners) | C15: Tatenda | G15: 21/04/26 | H15: ='Report Tracker'!H14 -> Submitted
A16: 11 | B16: Mimosa Corporate Funds | C16: Tino | G16: 26/04/26 | H16: ='Report Tracker'!H15 -> Complete
A17: 12 | B17: Zimnat Funds | C17: Tino | G17: 30/04/26 | H17: ='Report Tracker'!H16 -> Complete
A18: 13 | B18: Whitestone School Trust PF | C18: Tino | G18: 22/04/26 | H18: ='Report Tracker'!H17 -> Complete
A19: Anotida: 0/13 complete (0%)
B21: ARNOLD — 12 clients
A22: # | B22: Client | C22: CRM | D22: Submitted | E22: Reviewed | F22: Sent | G22: Due | H22: Status
A23: 1 | B23: Marsh Employees PF | C23: Tapiwa | G23: 27/04/26 | H23: ='Report Tracker'!H18 -> Submitted
A24: 2 | B24: Zimnat Group Staff PF | C24: Tatenda | H24: ='Report Tracker'!H19 -> Pending
A25: 3 | B25: Falcon College PF | C25: Tino | G25: 27/04/26 | H25: ='Report Tracker'!H20 -> Complete
A26: 4 | B26: Girls College | C26: Tino | G26: 28/04/26 | H26: ='Report Tracker'!H21 -> Complete
A27: 5 | B27: Masiyephambili Schools Trust PF | C27: Tino | G27: 29/04/26 | H27: ='Report Tracker'!H22 -> Complete
A28: 6 | B28: Minerva Provident | C28: Tino | H28: ='Report Tracker'!H23 -> Complete
A29: 7 | B29: Minerva Risk Advisors | C29: Tino | G29: 20/04/26 | H29: ='Report Tracker'!H24 -> Complete
A30: 8 | B30: Minerva Umbrella Fund | C30: Tino | G30: 21/04/26 | H30: ='Report Tracker'!H25 -> Complete
B31: TIMB Pension Fund | C31: Tapiwa | G31: 17/04/26 | H31: ='Report Tracker'!H26 -> Complete
B32: Petrotrade Pension Fund | C32: Tari | G32: 21/04/26 | H32: ='Report Tracker'!H27 -> Complete
A33: 9 | B33: Edgars Actives PF | C33: Tino | G33: 23/04/26 | H33: ='Report Tracker'!H28 -> Complete
A34: 10 | B34: Edgars Pensioners PF | C34: Tino | G34: 24/04/26 | H34: ='Report Tracker'!H29 -> Complete
A35: Arnold: 0/12 complete (0%)
B37: ELIZABETH — 12 clients
A38: # | B38: Client | C38: CRM | D38: Submitted | E38: Reviewed | F38: Sent | G38: Due | H38: Status
A39: 1 | B39: EY Pension Fund | C39: Tapiwa | G39: 17/04/25 | H39: ='Report Tracker'!H30 -> Complete
A40: 2 | B40: Zimsec Pension Fund | C40: Tapiwa | G40: 21/04/26 | H40: ='Report Tracker'!H31 -> Submitted
A41: 3 | B41: Zambezi River Authority | C41: Tapiwa | G41: 23/04/26 | H41: ='Report Tracker'!H32 -> Submitted
A42: 4 | B42: NBS | C42: Tapiwa | G42: 22/04/26 | H42: ='Report Tracker'!H33 -> Submitted
A43: 5 | B43: Goldridge | C43: Tapiwa | G43: 30/4/2026 | H43: ='Report Tracker'!H34 -> Complete
A44: 6 | B44: Unilever Zimbabwe PF | C44: Tapiwa | G44: 20/04/26 | H44: ='Report Tracker'!H35 -> Complete
...
